<?xml version="1.0" encoding="utf-8" ?>
<!-- This URDF was automatically created by SolidWorks to URDF Exporter! Originally created by Stephen Brawner (brawner@gmail.com) 
     Commit Version: 1.6.0-4-g7f85cfe  Build Version: 1.6.7995.38578
     For more information, please see http://wiki.ros.org/sw_urdf_exporter -->
<robot name="manipulator">
    <link name="base_link">
        <inertial>
            <origin xyz="-1.3252E-19 1.3599E-17 -0.0059926" rpy="0 0 0" />
            <mass value="0.51184" />
            <inertia ixx="0.002628" ixy="-7.0726E-20" ixz="2.275E-21" iyy="0.0018259" iyz="-5.9169E-21" izz="0.0044418" />
        </inertial>
        <visual>
            <origin xyz="0 0 0" rpy="0 0 0" />
            <geometry>
                <mesh filename="package://manipulator/meshes/base_link.STL" />
            </geometry>
            <material name="">
                <color rgba="1 1 1 1" />
            </material>
        </visual>
        <collision>
            <origin xyz="0 0 0" rpy="0 0 0" />
            <geometry>
                <mesh filename="package://manipulator/meshes/base_link.STL" />
            </geometry>
        </collision>
    </link>
    <link name="link1">
        <inertial>
            <origin xyz="0.030386 -1.2709E-10 -0.037371" rpy="0 0 0" />
            <mass value="0.11922" />
            <inertia ixx="0.00015227" ixy="-1.8986E-13" ixz="-4.0067E-05" iyy="0.000158" iyz="-1.9941E-13" izz="0.00012545" />
        </inertial>
        <visual>
            <origin xyz="0 0 0" rpy="0 0 0" />
            <geometry>
                <mesh filename="package://manipulator/meshes/link1.STL" />
            </geometry>
            <material name="">
                <color rgba="1 1 1 1" />
            </material>
        </visual>
        <collision>
            <origin xyz="0 0 0" rpy="0 0 0" />
            <geometry>
                <mesh filename="package://manipulator/meshes/link1.STL" />
            </geometry>
        </collision>
    </link>
    <joint name="joint1" type="revolute">
        <origin xyz="0 0 0.068" rpy="0 0 0" />
        <parent link="base_link" />
        <child link="link1" />
        <axis xyz="0 0 1" />
        <limit lower="-3.14" upper="3.14" effort="1000" velocity="1000" />
    </joint>
    <link name="link2">
        <inertial>
            <origin xyz="0.06725 7.8023E-07 -0.023323" rpy="0 0 0" />
            <mass value="0.13979" />
            <inertia ixx="0.00012945" ixy="-5.6227E-09" ixz="-3.4182E-05" iyy="0.00046719" iyz="-3.553E-09" izz="0.00052505" />
        </inertial>
        <visual>
            <origin xyz="0 0 0" rpy="0 0 0" />
            <geometry>
                <mesh filename="package://manipulator/meshes/link2.STL" />
            </geometry>
            <material name="">
                <color rgba="1 1 1 1" />
            </material>
        </visual>
        <collision>
            <origin xyz="0 0 0" rpy="0 0 0" />
            <geometry>
                <mesh filename="package://manipulator/meshes/link2.STL" />
            </geometry>
        </collision>
    </link>
    <joint name="joint2" type="revolute">
        <origin xyz="0.0005 0 0" rpy="0 -1.5708 0" />
        <parent link="link1" />
        <child link="link2" />
        <axis xyz="0 0 1" />
        <limit lower="-1.55" upper="1.55" effort="1000" velocity="1000" />
    </joint>
    <link name="link3">
        <inertial>
            <origin xyz="0.020827 4.4786E-09 -0.029773" rpy="0 0 0" />
            <mass value="0.084191" />
            <inertia ixx="9.0528E-05" ixy="5.8868E-13" ixz="-2.2221E-05" iyy="8.6433E-05" iyz="7.3347E-12" izz="6.8122E-05" />
        </inertial>
        <visual>
            <origin xyz="0 0 0" rpy="0 0 0" />
            <geometry>
                <mesh filename="package://manipulator/meshes/link3.STL" />
            </geometry>
            <material name="">
                <color rgba="1 1 1 1" />
            </material>
        </visual>
        <collision>
            <origin xyz="0 0 0" rpy="0 0 0" />
            <geometry>
                <mesh filename="package://manipulator/meshes/link3.STL" />
            </geometry>
        </collision>
    </link>
    <joint name="joint3" type="revolute">
        <origin xyz="0.206 0 0" rpy="0 1.5708 0" />
        <parent link="link2" />
        <child link="link3" />
        <axis xyz="0 0 1" />
        <limit lower="-3.14" upper="3.14" effort="1000" velocity="1000" />
    </joint>
    <link name="link4">
        <inertial>
            <origin xyz="0.060448 -2.029E-06 -0.021637" rpy="0 0 0" />
            <mass value="0.12668" />
            <inertia ixx="0.00010883" ixy="-4.5086E-09" ixz="-1.4983E-05" iyy="0.000282" iyz="1.4197E-09" izz="0.00032325" />
        </inertial>
        <visual>
            <origin xyz="0 0 0" rpy="0 0 0" />
            <geometry>
                <mesh filename="package://manipulator/meshes/link4.STL" />
            </geometry>
            <material name="">
                <color rgba="1 1 1 1" />
            </material>
        </visual>
        <collision>
            <origin xyz="0 0 0" rpy="0 0 0" />
            <geometry>
                <mesh filename="package://manipulator/meshes/link4.STL" />
            </geometry>
        </collision>
    </link>
    <joint name="joint4" type="revolute">
        <origin xyz="-0.003 0 0" rpy="0 -1.5708 0" />
        <parent link="link3" />
        <child link="link4" />
        <axis xyz="0 0 1" />
        <limit lower="-1.55" upper="1.55" effort="1000" velocity="1000" />
    </joint>
    <link name="link5">
        <inertial>
            <origin xyz="0.022751 -2.3087E-06 -0.029741" rpy="0 0 0" />
            <mass value="0.085932" />
            <inertia ixx="9.0587E-05" ixy="1.1198E-12" ixz="-2.3383E-05" iyy="8.9687E-05" iyz="9.2463E-16" izz="7.2974E-05" />
        </inertial>
        <visual>
            <origin xyz="0 0 0" rpy="0 0 0" />
            <geometry>
                <mesh filename="package://manipulator/meshes/link5.STL" />
            </geometry>
            <material name="">
                <color rgba="1 1 1 1" />
            </material>
        </visual>
        <collision>
            <origin xyz="0 0 0" rpy="0 0 0" />
            <geometry>
                <mesh filename="package://manipulator/meshes/link5.STL" />
            </geometry>
        </collision>
    </link>
    <joint name="joint5" type="revolute">
        <origin xyz="0.182 0 0" rpy="0 1.5708 0" />
        <parent link="link4" />
        <child link="link5" />
        <axis xyz="0 0 1" />
        <limit lower="-3.14" upper="3.14" effort="1000" velocity="1000" />
    </joint>
    <link name="link6">
        <inertial>
            <origin xyz="0.050634 2.0202E-06 -0.019016" rpy="0 0 0" />
            <mass value="0.091478" />
            <inertia ixx="6.4629E-05" ixy="6.6911E-10" ixz="-1.1104E-05" iyy="0.00019323" iyz="-1.2896E-10" izz="0.00022002" />
        </inertial>
        <visual>
            <origin xyz="0 0 0" rpy="0 0 0" />
            <geometry>
                <mesh filename="package://manipulator/meshes/link6.STL" />
            </geometry>
            <material name="">
                <color rgba="1 1 1 1" />
            </material>
        </visual>
        <collision>
            <origin xyz="0 0 0" rpy="0 0 0" />
            <geometry>
                <mesh filename="package://manipulator/meshes/link6.STL" />
            </geometry>
        </collision>
    </link>
    <joint name="joint6" type="revolute">
        <origin xyz="0 0 0" rpy="0 -1.5708 0" />
        <parent link="link5" />
        <child link="link6" />
        <axis xyz="0 0 1" />
        <limit lower="-1.55" upper="1.55" effort="1000" velocity="1000" />
    </joint>
    <link name="link7">
        <inertial>
            <origin xyz="4.1157E-05 7.5281E-05 0.023371" rpy="0 0 0" />
            <mass value="0.19202" />
            <inertia ixx="6.5362E-05" ixy="-3.5129E-08" ixz="8.2062E-08" iyy="6.5748E-05" iyz="1.4861E-07" izz="0.00011035" />
        </inertial>
        <visual>
            <origin xyz="0 0 0" rpy="0 0 0" />
            <geometry>
                <mesh filename="package://manipulator/meshes/link7.STL" />
            </geometry>
            <material name="">
                <color rgba="1 1 1 1" />
            </material>
        </visual>
        <collision>
            <origin xyz="0 0 0" rpy="0 0 0" />
            <geometry>
                <mesh filename="package://manipulator/meshes/link7.STL" />
            </geometry>
        </collision>
    </link>
    <joint name="joint7" type="revolute">
        <origin xyz="0.1161 0 0" rpy="0 1.5708 0" />
        <parent link="link6" />
        <child link="link7" />
        <axis xyz="0 0 1" />
        <limit lower="-3.14" upper="3.14" effort="1000" velocity="1000" />
    </joint>
    <transmission name="trans_joint1">
        <type>transmission_interface/SimpleTransmission</type>
        <joint name="joint1">
            <hardwareInterface>hardware_interface/EffortJointInterface</hardwareInterface>
        </joint>
        <actuator name="joint1_motor">
            <hardwareInterface>hardware_interface/EffortJointInterface</hardwareInterface>
            <mechanicalReduction>1</mechanicalReduction>
        </actuator>
    </transmission>
    <transmission name="trans_joint2">
        <type>transmission_interface/SimpleTransmission</type>
        <joint name="joint2">
            <hardwareInterface>hardware_interface/EffortJointInterface</hardwareInterface>
        </joint>
        <actuator name="joint2_motor">
            <hardwareInterface>hardware_interface/EffortJointInterface</hardwareInterface>
            <mechanicalReduction>1</mechanicalReduction>
        </actuator>
    </transmission>
    <transmission name="trans_joint3">
        <type>transmission_interface/SimpleTransmission</type>
        <joint name="joint3">
            <hardwareInterface>hardware_interface/EffortJointInterface</hardwareInterface>
        </joint>
        <actuator name="joint3_motor">
            <hardwareInterface>hardware_interface/EffortJointInterface</hardwareInterface>
            <mechanicalReduction>1</mechanicalReduction>
        </actuator>
    </transmission>
    <transmission name="trans_joint4">
        <type>transmission_interface/SimpleTransmission</type>
        <joint name="joint4">
            <hardwareInterface>hardware_interface/EffortJointInterface</hardwareInterface>
        </joint>
        <actuator name="joint4_motor">
            <hardwareInterface>hardware_interface/EffortJointInterface</hardwareInterface>
            <mechanicalReduction>1</mechanicalReduction>
        </actuator>
    </transmission>
    <transmission name="trans_joint5">
        <type>transmission_interface/SimpleTransmission</type>
        <joint name="joint5">
            <hardwareInterface>hardware_interface/EffortJointInterface</hardwareInterface>
        </joint>
        <actuator name="joint5_motor">
            <hardwareInterface>hardware_interface/EffortJointInterface</hardwareInterface>
            <mechanicalReduction>1</mechanicalReduction>
        </actuator>
    </transmission>
    <transmission name="trans_joint6">
        <type>transmission_interface/SimpleTransmission</type>
        <joint name="joint6">
            <hardwareInterface>hardware_interface/EffortJointInterface</hardwareInterface>
        </joint>
        <actuator name="joint6_motor">
            <hardwareInterface>hardware_interface/EffortJointInterface</hardwareInterface>
            <mechanicalReduction>1</mechanicalReduction>
        </actuator>
    </transmission>
    <transmission name="trans_joint7">
        <type>transmission_interface/SimpleTransmission</type>
        <joint name="joint7">
            <hardwareInterface>hardware_interface/EffortJointInterface</hardwareInterface>
        </joint>
        <actuator name="joint7_motor">
            <hardwareInterface>hardware_interface/EffortJointInterface</hardwareInterface>
            <mechanicalReduction>1</mechanicalReduction>
        </actuator>
    </transmission>
    <gazebo>
        <plugin name="gazebo_ros_control" filename="libgazebo_ros_control.so">
            <robotNamespace>/</robotNamespace>
        </plugin>
    </gazebo>
</robot>

