<?xml version="1.0" encoding="utf-8"?>
<!-- This URDF was automatically created by SolidWorks to URDF Exporter! Originally created by Stephen Brawner (brawner@gmail.com) 
     Commit Version: 1.6.0-4-g7f85cfe  Build Version: 1.6.7995.38578
     For more information, please see http://wiki.ros.org/sw_urdf_exporter -->
<robot

  name="manipulator">
   <!--将基座与世界坐标系固连，防止基座乱动，注意补偿base_link与link1之间的偏移，值越大越超过地面就好，有点小bug-->
  <link name="world" />
  <joint name="world_joint" type="fixed">
        <parent link="world" />
        <child link="base_link" />
        <origin xyz="0 0 0.1" rpy="0 0 0" />
    </joint>
  <link
    name="base_link">
    <inertial>
      <origin
        xyz="-1.3252E-19 1.3599E-17 -0.0059926"
        rpy="0 0 0" />
      <mass
        value="0.51184" />
      <inertia ixx="10" ixy="-0" ixz="0" iyy="10" iyz="0" izz="10" />
    </inertial>
    <visual>
      <origin
        xyz="0 0 0"
        rpy="0 0 0" />
      <geometry>
        <mesh
          filename="package://manipulator/meshes/base_link.STL" />
      </geometry>
      <material
        name="">
        <color
          rgba="1 1 1 1" />
      </material>
    </visual>
    <collision>
      <origin
        xyz="0 0 0"
        rpy="0 0 0" />
      <geometry>
        <mesh
          filename="package://manipulator/meshes/base_link.STL" />
      </geometry>
    </collision>
  </link>
  <link
    name="link1">
    <inertial>
      <origin
        xyz="0.030386 -1.2709E-10 -0.037371"
        rpy="0 0 0" />
      <mass
        value="0.11922" />
      <inertia ixx="10" ixy="-0" ixz="0" iyy="10" iyz="0" izz="10" />
    </inertial>
    <visual>
      <origin
        xyz="0 0 0"
        rpy="0 0 0" />
      <geometry>
        <mesh
          filename="package://manipulator/meshes/link1.STL" />
      </geometry>
      <material
        name="">
        <color
          rgba="1 1 1 1" />
      </material>
    </visual>
    <collision>
      <origin
        xyz="0 0 0"
        rpy="0 0 0" />
      <geometry>
        <mesh
          filename="package://manipulator/meshes/link1.STL" />
      </geometry>
    </collision>
  </link>
  <joint
    name="joint1"
    type="revolute">
    <origin
      xyz="0 0 0.068"
      rpy="0 0 0" />
    <parent
      link="base_link" />
    <child
      link="link1" />
    <axis
      xyz="0 0 1" />
    <limit
      lower="-3.14"
      upper="3.14"
      effort="1000"
      velocity="1000" />
  </joint>
  <link
    name="link2">
    <inertial>
      <origin
        xyz="0.06725 7.8023E-07 -0.023323"
        rpy="0 0 0" />
      <mass
        value="0.13979" />
      <inertia ixx="10" ixy="-0" ixz="0" iyy="10" iyz="0" izz="10" />
    </inertial>
    <visual>
      <origin
        xyz="0 0 0"
        rpy="0 0 0" />
      <geometry>
        <mesh
          filename="package://manipulator/meshes/link2.STL" />
      </geometry>
      <material
        name="">
        <color
          rgba="1 1 1 1" />
      </material>
    </visual>
    <collision>
      <origin
        xyz="0 0 0"
        rpy="0 0 0" />
      <geometry>
        <mesh
          filename="package://manipulator/meshes/link2.STL" />
      </geometry>
    </collision>
  </link>
  <joint
    name="joint2"
    type="revolute">
    <origin
      xyz="0.0005 0 0"
      rpy="0 -1.5708 0" />
    <parent
      link="link1" />
    <child
      link="link2" />
    <axis
      xyz="0 0 1" />
    <limit
      lower="-1.55"
      upper="1.55"
      effort="1000"
      velocity="1000" />
  </joint>
  <link
    name="link3">
    <inertial>
      <origin
        xyz="0.020827 4.4786E-09 -0.029773"
        rpy="0 0 0" />
      <mass
        value="0.084191" />
      <inertia ixx="10" ixy="-0" ixz="0" iyy="10" iyz="0" izz="10" />
    </inertial>
    <visual>
      <origin
        xyz="0 0 0"
        rpy="0 0 0" />
      <geometry>
        <mesh
          filename="package://manipulator/meshes/link3.STL" />
      </geometry>
      <material
        name="">
        <color
          rgba="1 1 1 1" />
      </material>
    </visual>
    <collision>
      <origin
        xyz="0 0 0"
        rpy="0 0 0" />
      <geometry>
        <mesh
          filename="package://manipulator/meshes/link3.STL" />
      </geometry>
    </collision>
  </link>
  <joint
    name="joint3"
    type="revolute">
    <origin
      xyz="0.206 0 0"
      rpy="0 1.5708 0" />
    <parent
      link="link2" />
    <child
      link="link3" />
    <axis
      xyz="0 0 1" />
    <limit
      lower="-3.14"
      upper="3.14"
      effort="1000"
      velocity="1000" />
  </joint>
  <link
    name="link4">
    <inertial>
      <origin
        xyz="0.060448 -2.029E-06 -0.021637"
        rpy="0 0 0" />
      <mass
        value="0.12668" />
      <inertia ixx="10" ixy="-0" ixz="0" iyy="10" iyz="0" izz="10" />
    </inertial>
    <visual>
      <origin
        xyz="0 0 0"
        rpy="0 0 0" />
      <geometry>
        <mesh
          filename="package://manipulator/meshes/link4.STL" />
      </geometry>
      <material
        name="">
        <color
          rgba="1 1 1 1" />
      </material>
    </visual>
    <collision>
      <origin
        xyz="0 0 0"
        rpy="0 0 0" />
      <geometry>
        <mesh
          filename="package://manipulator/meshes/link4.STL" />
      </geometry>
    </collision>
  </link>
  <joint
    name="joint4"
    type="revolute">
    <origin
      xyz="-0.003 0 0"
      rpy="0 -1.5708 0" />
    <parent
      link="link3" />
    <child
      link="link4" />
    <axis
      xyz="0 0 1" />
    <limit
      lower="-1.3"
      upper="1.3"
      effort="1000"
      velocity="1000" />
  </joint>
  <link
    name="link5">
    <inertial>
      <origin
        xyz="0.022751 -2.3087E-06 -0.029741"
        rpy="0 0 0" />
      <mass
        value="0.085932" />
      <inertia ixx="10" ixy="-0" ixz="0" iyy="10" iyz="0" izz="10" />
    </inertial>
    <visual>
      <origin
        xyz="0 0 0"
        rpy="0 0 0" />
      <geometry>
        <mesh
          filename="package://manipulator/meshes/link5.STL" />
      </geometry>
      <material
        name="">
        <color
          rgba="1 1 1 1" />
      </material>
    </visual>
    <collision>
      <origin
        xyz="0 0 0"
        rpy="0 0 0" />
      <geometry>
        <mesh
          filename="package://manipulator/meshes/link5.STL" />
      </geometry>
    </collision>
  </link>
  <joint
    name="joint5"
    type="revolute">
    <origin
      xyz="0.182 0 0"
      rpy="0 1.5708 0" />
    <parent
      link="link4" />
    <child
      link="link5" />
    <axis
      xyz="0 0 1" />
    <limit
      lower="-3.14"
      upper="3.14"
      effort="1000"
      velocity="1000" />
  </joint>
  <link
    name="link6">
    <inertial>
      <origin
        xyz="0.050634 2.0202E-06 -0.019016"
        rpy="0 0 0" />
      <mass
        value="0.091478" />
      <inertia ixx="10" ixy="-0" ixz="0" iyy="10" iyz="0" izz="10" />
    </inertial>
    <visual>
      <origin
        xyz="0 0 0"
        rpy="0 0 0" />
      <geometry>
        <mesh
          filename="package://manipulator/meshes/link6.STL" />
      </geometry>
      <material
        name="">
        <color
          rgba="1 1 1 1" />
      </material>
    </visual>
    <collision>
      <origin
        xyz="0 0 0"
        rpy="0 0 0" />
      <geometry>
        <mesh
          filename="package://manipulator/meshes/link6.STL" />
      </geometry>
    </collision>
  </link>
  <joint
    name="joint6"
    type="revolute">
    <origin
      xyz="0 0 0"
      rpy="0 -1.5708 0" />
    <parent
      link="link5" />
    <child
      link="link6" />
    <axis
      xyz="0 0 1" />
    <limit
      lower="-1.55"
      upper="1.55"
      effort="1000"
      velocity="1000" />
  </joint>
  <link
    name="link7">
    <inertial>
      <origin
        xyz="4.1157E-05 7.5281E-05 0.023371"
        rpy="0 0 0" />
      <mass
        value="0.19202" />
      <inertia ixx="10" ixy="-0" ixz="0" iyy="10" iyz="0" izz="10" />
    </inertial>
    <visual>
      <origin
        xyz="0 0 0"
        rpy="0 0 0" />
      <geometry>
        <mesh
          filename="package://manipulator/meshes/link7.STL" />
      </geometry>
      <material
        name="">
        <color
          rgba="1 1 1 1" />
      </material>
    </visual>
    <collision>
      <origin
        xyz="0 0 0"
        rpy="0 0 0" />
      <geometry>
        <mesh
          filename="package://manipulator/meshes/link7.STL" />
      </geometry>
    </collision>
  </link>
  <joint
    name="joint7"
    type="revolute">
    <origin
      xyz="0.1161 0 0"
      rpy="0 1.5708 0" />
    <parent
      link="link6" />
    <child
      link="link7" />
    <axis
      xyz="0 0 1" />
    <limit
      lower="-3.14"
      upper="3.14"
      effort="1000"
      velocity="1000" />
  </joint>

  <transmission name="trans_joint1">
        <type>transmission_interface/SimpleTransmission</type>
        <joint name="joint1">
            <hardwareInterface>hardware_interface/PositionJointInterface</hardwareInterface>
        </joint>
        <actuator name="joint1_motor">
            <hardwareInterface>hardware_interface/PositionJointInterface</hardwareInterface>
            <mechanicalReduction>1</mechanicalReduction>
        </actuator>
  </transmission>
  <transmission name="trans_joint2">
      <type>transmission_interface/SimpleTransmission</type>
      <joint name="joint2">
          <hardwareInterface>hardware_interface/PositionJointInterface</hardwareInterface>
      </joint>
      <actuator name="joint2_motor">
          <hardwareInterface>hardware_interface/PositionJointInterface</hardwareInterface>
          <mechanicalReduction>1</mechanicalReduction>
      </actuator>
  </transmission>
  <transmission name="trans_joint3">
      <type>transmission_interface/SimpleTransmission</type>
      <joint name="joint3">
          <hardwareInterface>hardware_interface/PositionJointInterface</hardwareInterface>
      </joint>
      <actuator name="joint3_motor">
          <hardwareInterface>hardware_interface/PositionJointInterface</hardwareInterface>
          <mechanicalReduction>1</mechanicalReduction>
      </actuator>
  </transmission>
  <transmission name="trans_joint4">
      <type>transmission_interface/SimpleTransmission</type>
      <joint name="joint4">
          <hardwareInterface>hardware_interface/PositionJointInterface</hardwareInterface>
      </joint>
      <actuator name="joint4_motor">
          <hardwareInterface>hardware_interface/PositionJointInterface</hardwareInterface>
          <mechanicalReduction>1</mechanicalReduction>
      </actuator>
  </transmission>
  <transmission name="trans_joint5">
      <type>transmission_interface/SimpleTransmission</type>
      <joint name="joint5">
          <hardwareInterface>hardware_interface/PositionJointInterface</hardwareInterface>
      </joint>
      <actuator name="joint5_motor">
          <hardwareInterface>hardware_interface/PositionJointInterface</hardwareInterface>
          <mechanicalReduction>1</mechanicalReduction>
      </actuator>
  </transmission>
  <transmission name="trans_joint6">
      <type>transmission_interface/SimpleTransmission</type>
      <joint name="joint6">
          <hardwareInterface>hardware_interface/PositionJointInterface</hardwareInterface>
      </joint>
      <actuator name="joint6_motor">
          <hardwareInterface>hardware_interface/PositionJointInterface</hardwareInterface>
          <mechanicalReduction>1</mechanicalReduction>
      </actuator>
  </transmission>
  <transmission name="trans_joint7">
      <type>transmission_interface/SimpleTransmission</type>
      <joint name="joint7">
          <hardwareInterface>hardware_interface/PositionJointInterface</hardwareInterface>
      </joint>
      <actuator name="joint7_motor">
          <hardwareInterface>hardware_interface/PositionJointInterface</hardwareInterface>
          <mechanicalReduction>1</mechanicalReduction>
      </actuator>
  </transmission>
  <gazebo>
      <plugin name="gazebo_ros_control" filename="libgazebo_ros_control.so">
          <robotNamespace>/</robotNamespace>
          <robotSimType>gazebo_ros_control/DefaultRobotHWSim</robotSimType>
          <legacyModeNS>true</legacyModeNS>
      </plugin>
  </gazebo>

</robot>